let a = 10;
try {
    a = b; // First ReferenceError
} catch (error) {
    try {
        console.log('first catch')
        console.log(b); // Second ReferenceError
    } catch {
        console.log("Second catch!"); // -> Second catch!
    }
} finally {
    console.log("Finally!"); // -> Finally!
}